[2022-12-04T18:28:25.408+0000] {taskinstance.py:1087} INFO - Dependencies all met for <TaskInstance: predict_data.predict_data scheduled__2022-12-02T00:00:00+00:00 [queued]>
[2022-12-04T18:28:25.416+0000] {taskinstance.py:1087} INFO - Dependencies all met for <TaskInstance: predict_data.predict_data scheduled__2022-12-02T00:00:00+00:00 [queued]>
[2022-12-04T18:28:25.417+0000] {taskinstance.py:1283} INFO - 
--------------------------------------------------------------------------------
[2022-12-04T18:28:25.418+0000] {taskinstance.py:1284} INFO - Starting attempt 1 of 1
[2022-12-04T18:28:25.419+0000] {taskinstance.py:1285} INFO - 
--------------------------------------------------------------------------------
[2022-12-04T18:28:25.429+0000] {taskinstance.py:1304} INFO - Executing <Task(PythonOperator): predict_data> on 2022-12-02 00:00:00+00:00
[2022-12-04T18:28:25.436+0000] {standard_task_runner.py:55} INFO - Started process 8024 to run task
[2022-12-04T18:28:25.441+0000] {standard_task_runner.py:82} INFO - Running: ['***', 'tasks', 'run', 'predict_data', 'predict_data', 'scheduled__2022-12-02T00:00:00+00:00', '--job-id', '96', '--raw', '--subdir', 'DAGS_FOLDER/predict_values.py', '--cfg-path', '/tmp/tmpylznmjn_']
[2022-12-04T18:28:25.444+0000] {standard_task_runner.py:83} INFO - Job 96: Subtask predict_data
[2022-12-04T18:28:25.511+0000] {task_command.py:389} INFO - Running <TaskInstance: predict_data.predict_data scheduled__2022-12-02T00:00:00+00:00 [running]> on host c7dedbf79ea9
[2022-12-04T18:28:25.565+0000] {taskinstance.py:1513} INFO - Exporting the following env vars:
AIRFLOW_CTX_DAG_OWNER=***
AIRFLOW_CTX_DAG_ID=predict_data
AIRFLOW_CTX_TASK_ID=predict_data
AIRFLOW_CTX_EXECUTION_DATE=2022-12-02T00:00:00+00:00
AIRFLOW_CTX_TRY_NUMBER=1
AIRFLOW_CTX_DAG_RUN_ID=scheduled__2022-12-02T00:00:00+00:00
[2022-12-04T18:28:25.604+0000] {taskinstance.py:1772} ERROR - Task failed with exception
Traceback (most recent call last):
  File "/home/airflow/.local/lib/python3.7/site-packages/airflow/operators/python.py", line 175, in execute
    return_value = self.execute_callable()
  File "/home/airflow/.local/lib/python3.7/site-packages/airflow/operators/python.py", line 192, in execute_callable
    return self.python_callable(*self.op_args, **self.op_kwargs)
  File "/opt/airflow/dags/predict_values.py", line 27, in _predict_data
    data = pd.read_csv(path_to_data)
  File "/home/airflow/.local/lib/python3.7/site-packages/pandas/util/_decorators.py", line 311, in wrapper
    return func(*args, **kwargs)
  File "/home/airflow/.local/lib/python3.7/site-packages/pandas/io/parsers/readers.py", line 586, in read_csv
    return _read(filepath_or_buffer, kwds)
  File "/home/airflow/.local/lib/python3.7/site-packages/pandas/io/parsers/readers.py", line 482, in _read
    parser = TextFileReader(filepath_or_buffer, **kwds)
  File "/home/airflow/.local/lib/python3.7/site-packages/pandas/io/parsers/readers.py", line 811, in __init__
    self._engine = self._make_engine(self.engine)
  File "/home/airflow/.local/lib/python3.7/site-packages/pandas/io/parsers/readers.py", line 1040, in _make_engine
    return mapping[engine](self.f, **self.options)  # type: ignore[call-arg]
  File "/home/airflow/.local/lib/python3.7/site-packages/pandas/io/parsers/c_parser_wrapper.py", line 51, in __init__
    self._open_handles(src, kwds)
  File "/home/airflow/.local/lib/python3.7/site-packages/pandas/io/parsers/base_parser.py", line 229, in _open_handles
    errors=kwds.get("encoding_errors", "strict"),
  File "/home/airflow/.local/lib/python3.7/site-packages/pandas/io/common.py", line 707, in get_handle
    newline="",
FileNotFoundError: [Errno 2] No such file or directory: 'data/raw/2022-12-02/data.csv'
[2022-12-04T18:28:25.617+0000] {taskinstance.py:1327} INFO - Marking task as FAILED. dag_id=predict_data, task_id=predict_data, execution_date=20221202T000000, start_date=20221204T182825, end_date=20221204T182825
[2022-12-04T18:28:25.625+0000] {standard_task_runner.py:105} ERROR - Failed to execute job 96 for task predict_data ([Errno 2] No such file or directory: 'data/raw/2022-12-02/data.csv'; 8024)
[2022-12-04T18:28:25.655+0000] {local_task_job.py:159} INFO - Task exited with return code 1
[2022-12-04T18:28:25.671+0000] {taskinstance.py:2582} INFO - 0 downstream tasks scheduled from follow-on schedule check
