[2022-12-04T18:09:32.953+0000] {taskinstance.py:1087} INFO - Dependencies all met for <TaskInstance: model_training.validate_model manual__2022-12-04T18:09:15.186734+00:00 [queued]>
[2022-12-04T18:09:32.962+0000] {taskinstance.py:1087} INFO - Dependencies all met for <TaskInstance: model_training.validate_model manual__2022-12-04T18:09:15.186734+00:00 [queued]>
[2022-12-04T18:09:32.963+0000] {taskinstance.py:1283} INFO - 
--------------------------------------------------------------------------------
[2022-12-04T18:09:32.964+0000] {taskinstance.py:1284} INFO - Starting attempt 1 of 1
[2022-12-04T18:09:32.966+0000] {taskinstance.py:1285} INFO - 
--------------------------------------------------------------------------------
[2022-12-04T18:09:32.976+0000] {taskinstance.py:1304} INFO - Executing <Task(PythonOperator): validate_model> on 2022-12-04 18:09:15.186734+00:00
[2022-12-04T18:09:32.985+0000] {standard_task_runner.py:55} INFO - Started process 6729 to run task
[2022-12-04T18:09:32.989+0000] {standard_task_runner.py:82} INFO - Running: ['***', 'tasks', 'run', 'model_training', 'validate_model', 'manual__2022-12-04T18:09:15.186734+00:00', '--job-id', '91', '--raw', '--subdir', 'DAGS_FOLDER/train_model.py', '--cfg-path', '/tmp/tmpsy8p4w_d']
[2022-12-04T18:09:32.993+0000] {standard_task_runner.py:83} INFO - Job 91: Subtask validate_model
[2022-12-04T18:09:33.061+0000] {task_command.py:389} INFO - Running <TaskInstance: model_training.validate_model manual__2022-12-04T18:09:15.186734+00:00 [running]> on host c7dedbf79ea9
[2022-12-04T18:09:33.123+0000] {taskinstance.py:1513} INFO - Exporting the following env vars:
AIRFLOW_CTX_DAG_OWNER=***
AIRFLOW_CTX_DAG_ID=model_training
AIRFLOW_CTX_TASK_ID=validate_model
AIRFLOW_CTX_EXECUTION_DATE=2022-12-04T18:09:15.186734+00:00
AIRFLOW_CTX_TRY_NUMBER=1
AIRFLOW_CTX_DAG_RUN_ID=manual__2022-12-04T18:09:15.186734+00:00
[2022-12-04T18:09:33.163+0000] {taskinstance.py:1772} ERROR - Task failed with exception
Traceback (most recent call last):
  File "/home/airflow/.local/lib/python3.7/site-packages/airflow/operators/python.py", line 175, in execute
    return_value = self.execute_callable()
  File "/home/airflow/.local/lib/python3.7/site-packages/airflow/operators/python.py", line 192, in execute_callable
    return self.python_callable(*self.op_args, **self.op_kwargs)
  File "/opt/airflow/dags/train_model.py", line 108, in _validate_model
    model = pickle.load(file)
  File "/usr/local/lib/python3.7/codecs.py", line 322, in decode
    (result, consumed) = self._buffer_decode(data, self.errors, final)
UnicodeDecodeError: 'utf-8' codec can't decode byte 0x80 in position 0: invalid start byte
[2022-12-04T18:09:33.176+0000] {taskinstance.py:1327} INFO - Marking task as FAILED. dag_id=model_training, task_id=validate_model, execution_date=20221204T180915, start_date=20221204T180932, end_date=20221204T180933
[2022-12-04T18:09:33.185+0000] {standard_task_runner.py:105} ERROR - Failed to execute job 91 for task validate_model ('utf-8' codec can't decode byte 0x80 in position 0: invalid start byte; 6729)
[2022-12-04T18:09:33.202+0000] {local_task_job.py:159} INFO - Task exited with return code 1
[2022-12-04T18:09:33.221+0000] {taskinstance.py:2582} INFO - 0 downstream tasks scheduled from follow-on schedule check
